Workbook

Sheet Инструкция
B1: ОЦЕНКА 360° РУКОВОДИТЕЛЕЙ ПРОЕКТОВ РЦК — ИНСТРУКЦИЯ ПО ПРОВЕДЕНИЮ
B3: Что такое оценка 360°. Руководитель проекта оценивается по ряду компетенций несколькими группами: его непосредственный руководитель, коллеги, подчинённые, внутренние клиенты (предприятия-участники, ФЦК, смежные подразделения), плюс самооценка. Это даёт картину «со всех сторон» и показывает слепые зоны — где человек оценивает себя выше, чем его видят окружающие.
B5: ШКАЛА ОЦЕНИВАНИЯ (для всех компетенций):
B6: 1 — Не соответствует: поведение не наблюдается, компетенция не проявляется
B7: 2 — Частично соответствует: проявления единичные, нестабильные
B8: 3 — Соответствует: устойчивое поведение, соответствует требованиям
B9: 4 — Высокий уровень: устойчиво превышает требования, пример для коллег
B10: 5 — Выдающийся: лучший в организации, менторит и обучает других
B12: ШАГИ ПРОВЕДЕНИЯ:
B13: 1. Подготовьте список опрашиваемых для каждого из 7 руководителей. Рекомендуемый состав: 1 непосредственный руководитель; 3–5 коллег (соседние руководители проектов); 3–5 подчинённых; 1–2 внутренних клиента (предприятия-участники, куратор/ФЦК). Самооценку руководитель заполняет сам. Всего на человека — 8–15 респондентов.
B14: 2. Проведите короткий инструктаж респондентов: цель оценки — развитие (не депремирование), шкала 1–5, конфиденциальность (результаты отдельных людей никому не показываются), срок — 2–3 недели.
B15: 3. Сбор оценок. Либо каждый респондент заполняет в листе «Оценки» только СВОЙ столбец в блоке того руководителя, которого он оценивает (файл по очереди передаётся), либо оценки собираются онлайн-формой, а вы вносите их в лист «Оценки». Целые числа от 1 до 5 (есть проверка ввода).
... B28: • Формат плана развития и шкала уровней (0–3, шаг 0,5) — приложение № 6 МР-02-2025 «Организация работы региональных центров компетенций в сфере производительности труда в субъектах РФ», ред. 1, утв. ФЦК 28.01.2025. Пункт 10.4 МР: матрица компетенций и планы развития сотрудников размещаются в инфоцентре РЦК.

Sheet Компетенции
A1: Модель профессиональных компетенций руководителя проекта РЦК (приложение № 3 МР, 37 компетенций)
A2: Наименования — точно по приложению № 3 МР-02-2025 (ред. 1). Цвет — группы «Действий». При изменении списка сохраняйте порядок строк на листах «Оценки» и «Сводка».
A3: № | B3: Ссылка на МР | C3: Группа («Действие») приложения № 3 | D3: Компетенция (действие / навык)
A4: 1 | B4: 1.1 | C4: Проведение отбора предприятий для участия в федеральном и региональном проектах, проведение выбора потока | D4: Проведение оценки на соответствие предприятия обязательным критериям
A5: 2 | B5: 1.2 | C5: Проведение отбора предприятий для участия в федеральном и региональном проектах, проведение выбора потока | D5: Проведение оценки готовности руководства предприятия к участию в проекте (интервью)
A6: 3 | B6: 1.3 | C6: Проведение отбора предприятий для участия в федеральном и региональном проектах, проведение выбора потока | D6: Проведение визуальной оценки производственного процесса на предприятии (визит на площадку)
A7: 4 | B7: 1.4 | C7: Проведение отбора предприятий для участия в федеральном и региональном проектах, проведение выбора потока | D7: Вовлечение руководства предприятий в федеральный проект
A8: 5 | B8: 1.5 | C8: Проведение отбора предприятий для участия в федеральном и региональном проектах, проведение выбора потока | D8: Подписание соглашения о сотрудничестве между РЦК и предприятием
A9: 6 | B9: 2.1 | C9: Реализация мероприятий по развертыванию программы повышения производительности труда на предприятии согласно стандартной последовательности и срокам исполнения проекта | D9: Реализация организационных вех программы
A10: 7 | B10: 2.1 | C10: Реализация мероприятий по развертыванию программы повышения производительности труда на предприятии согласно стандартной последовательности и срокам исполнения проекта | D10: Формирование проектного офиса
A11: 8 | B11: 2.2 | C11: Реализация мероприятий по развертыванию программы повышения производительности труда на предприятии согласно стандартной последовательности и срокам исполнения проекта | D11: Определение перечня вовлеченных лиц и рамок проекта; создание рабочей группы для работы с пилотным потоком
A12: 9 | B12: 2.2 | C12: Реализация мероприятий по развертыванию программы повышения производительности труда на предприятии согласно стандартной последовательности и срокам исполнения проекта | D12: Выявление степени готовности предприятия к изменениям
A13: 10 | B13: 2.2 | C13: Реализация мероприятий по развертыванию программы повышения производительности труда на предприятии согласно стандартной последовательности и срокам исполнения проекта | D13: Составление плана ключевых событий
A14: 11 | B14: 2.2 | C14: Реализация мероприятий по развертыванию программы повышения производительности труда на предприятии согласно стандартной последовательности и срокам исполнения проекта | D14: Разработка и корректировка плана мероприятий (основные этапы, сроки, ответственные) по достижению целевого состояния
A15: 12 | B15: 2.2 | C15: Реализация мероприятий по развертыванию программы повышения производительности труда на предприятии согласно стандартной последовательности и срокам исполнения проекта | D15: Проведение анализа показателей проектов повышения производительности труда
... A40: 37 | B40: 4.5 | C40: Поддержка рабочих групп / проектных офисов на предприятиях-участниках | D40: Ведение мониторинга проектов в подсистеме «Совместная работа» на ИТ-платформе

Sheet Оценки
A1: СЫРЫЕ ОЦЕНКИ (целые числа 1–5). Каждый респондент заполняет ТОЛЬКО свой столбец и ТОЛЬКО блок руководителя, которого он оценивает. Столбцы «Коллега N / Подчинённый N» — конкретные люди, имена фиксирует организатор отдельно (не в таблице!). Лист видит только организатор.
A2: № | B2: Компетенция (приложение № 3 МР) | C2: Руководитель | D2: Коллега 1 | E2: Коллега 2 | F2: Коллега 3 | G2: Подчинённый 1 | H2: Подчинённый 2 | I2: Подчинённый 3 | J2: Клиент 1 | K2: Сам (сама)
A3: РП-1 — Смирнов А. П. (ПРИМЕР — замените данные)
A4: 1 | B4: Проведение оценки на соответствие предприятия обязательным критериям | C4: 4 | D4: 4 | E4: 3 | F4: 3 | G4: 4 | H4: 3 | I4: 3 | J4: 4 | K4: 5
A5: 2 | B5: Проведение оценки готовности руководства предприятия к участию в проекте (интервью) | C5: 3 | D5: 3 | E5: 3 | F5: 4 | G5: 3 | H5: 4 | I5: 3 | J5: 3 | K5: 3
A6: 3 | B6: Проведение визуальной оценки производственного процесса на предприятии (визит на площадку) | C6: 3 | D6: 3 | E6: 4 | F6: 3 | G6: 3 | H6: 3 | I6: 4 | J6: 3 | K6: 3
A7: 4 | B7: Вовлечение руководства предприятий в федеральный проект | C7: 4 | D7: 4 | E7: 3 | F7: 3 | G7: 3 | H7: 3 | I7: 3 | J7: 3 | K7: 4
A8: 5 | B8: Подписание соглашения о сотрудничестве между РЦК и предприятием | C8: 3 | D8: 3 | E8: 3 | F8: 4 | G8: 4 | H8: 3 | I8: 3 | J8: 3 | K8: 3
A9: 6 | B9: Реализация организационных вех программы | C9: 3 | D9: 3 | E9: 4 | F9: 3 | G9: 3 | H9: 4 | I9: 3 | J9: 4 | K9: 3
A10: 7 | B10: Формирование проектного офиса | C10: 4 | D10: 4 | E10: 3 | F10: 3 | G10: 3 | H10: 3 | I10: 4 | J10: 3 | K10: 4
A11: 8 | B11: Определение перечня вовлеченных лиц и рамок проекта; создание рабочей группы для работы с пилотным потоком | C11: 3 | D11: 3 | E11: 3 | F11: 4 | G11: 3 | H11: 3 | I11: 3 | J11: 3 | K11: 4
A12: 9 | B12: Выявление степени готовности предприятия к изменениям | C12: 3 | D12: 3 | E12: 4 | F12: 3 | G12: 4 | H12: 3 | I12: 3 | J12: 3 | K12: 3
A13: 10 | B13: Составление плана ключевых событий | C13: 4 | D13: 4 | E13: 3 | F13: 3 | G13: 3 | H13: 4 | I13: 3 | J13: 3 | K13: 4
A14: 11 | B14: Разработка и корректировка плана мероприятий (основные этапы, сроки, ответственные) по достижению целевого состояния | C14: 3 | D14: 3 | E14: 3 | F14: 4 | G14: 3 | H14: 3 | I14: 4 | J14: 4 | K14: 3
A15: 12 | B15: Проведение анализа показателей проектов повышения производительности труда | C15: 3 | D15: 3 | E15: 4 | F15: 3 | G15: 3 | H15: 3 | I15: 3 | J15: 3 | K15: 3
... A40: 37 | B40: Ведение мониторинга проектов в подсистеме «Совместная работа» на ИТ-платформе | C40: 4 | D40: 4 | E40: 3 | F40: 3 | G40: 4 | H40: 3 | I40: 3 | J40: 3 | K40: 4
A42: РП-2 — (впишите ФИО руководителя проекта 2)
A43: 1 | B43: Проведение оценки на соответствие предприятия обязательным критериям
A44: 2 | B44: Проведение оценки готовности руководства предприятия к участию в проекте (интервью)
A45: 3 | B45: Проведение визуальной оценки производственного процесса на предприятии (визит на площадку)
A46: 4 | B46: Вовлечение руководства предприятий в федеральный проект
A47: 5 | B47: Подписание соглашения о сотрудничестве между РЦК и предприятием
A48: 6 | B48: Реализация организационных вех программы
A49: 7 | B49: Формирование проектного офиса
A50: 8 | B50: Определение перечня вовлеченных лиц и рамок проекта; создание рабочей группы для работы с пилотным потоком
A51: 9 | B51: Выявление степени готовности предприятия к изменениям
A52: 10 | B52: Составление плана ключевых событий
A53: 11 | B53: Разработка и корректировка плана мероприятий (основные этапы, сроки, ответственные) по достижению целевого состояния
A54: 12 | B54: Проведение анализа показателей проектов повышения производительности труда
... A79: 37 | B79: Ведение мониторинга проектов в подсистеме «Совместная работа» на ИТ-платформе
A81: РП-3 — (впишите ФИО руководителя проекта 3)
A82: 1 | B82: Проведение оценки на соответствие предприятия обязательным критериям
A83: 2 | B83: Проведение оценки готовности руководства предприятия к участию в проекте (интервью)
A84: 3 | B84: Проведение визуальной оценки производственного процесса на предприятии (визит на площадку)
A85: 4 | B85: Вовлечение руководства предприятий в федеральный проект
A86: 5 | B86: Подписание соглашения о сотрудничестве между РЦК и предприятием
A87: 6 | B87: Реализация организационных вех программы
A88: 7 | B88: Формирование проектного офиса
A89: 8 | B89: Определение перечня вовлеченных лиц и рамок проекта; создание рабочей группы для работы с пилотным потоком
A90: 9 | B90: Выявление степени готовности предприятия к изменениям
...

Sheet Сводка
A1: СВОДНАЯ ТАБЛИЦА РЕЗУЛЬТАТОВ 360 (считается автоматически из листа «Оценки»)
A2: «Другие» = среднее по группам руководитель/коллеги/подчинённые/клиент. «Разрыв» = самооценка минус «Другие» (красный ≥ 0,5 — слепая зона). «Сигналы»: «низкий уровень» — средний балл «Другие» ниже 3. Цвет строки — группа «Действий» (см. «Компетенции»).
A3: Руководитель проекта | B3: Компетенция (приложение № 3 МР) | C3: Себя | D3: Руководитель | E3: Коллеги (ср.) | F3: Подчинённые (ср.) | G3: Клиент (ср.) | H3: Другие (ср.) | I3: Разрыв (себя − другие) | J3: Сигналы
A4: Смирнов А. П. (ПРИМЕР) | B4: Проведение оценки на соответствие предприятия обязательным критериям | C4: =IF('Оценки'!K4="","",'Оценки'!K4) | D4: =IF('Оценки'!C4="","",'Оценки'!C4) | E4: =IF(COUNT('Оценки'!D4:F4)=0,"",AVERAGE('Оценки'!D4:F4)) | F4: =IF(COUNT('Оценки'!G4:I4)=0,"",AVERAGE('Оценки'!G4:I4)) | G4: =IF('Оценки'!J4="","",'Оценки'!J4) | H4: =IF(COUNT(D4:G4)=0,"",AVERAGE(D4:G4)) | I4: =IF(OR(C4="",H4=""),"",C4-H4) | J4: =IF(I4="","",IF(I4>=0.5,"⚠ переоценивает себя",IF(H4<3,"низкий уровень","")))
A5: Смирнов А. П. (ПРИМЕР) | B5: Проведение оценки готовности руководства предприятия к участию в проекте (интервью) | C5: =IF('Оценки'!K5="","",'Оценки'!K5) | D5: =IF('Оценки'!C5="","",'Оценки'!C5) | E5: =IF(COUNT('Оценки'!D5:F5)=0,"",AVERAGE('Оценки'!D5:F5)) | F5: =IF(COUNT('Оценки'!G5:I5)=0,"",AVERAGE('Оценки'!G5:I5)) | G5: =IF('Оценки'!J5="","",'Оценки'!J5) | H5: =IF(COUNT(D5:G5)=0,"",AVERAGE(D5:G5)) | I5: =IF(OR(C5="",H5=""),"",C5-H5) | J5: =IF(I5="","",IF(I5>=0.5,"⚠ переоценивает себя",IF(H5<3,"низкий уровень","")))
A6: Смирнов А. П. (ПРИМЕР) | B6: Проведение визуальной оценки производственного процесса на предприятии (визит на площадку) | C6: =IF('Оценки'!K6="","",'Оценки'!K6) | D6: =IF('Оценки'!C6="","",'Оценки'!C6) | E6: =IF(COUNT('Оценки'!D6:F6)=0,"",AVERAGE('Оценки'!D6:F6)) | F6: =IF(COUNT('Оценки'!G6:I6)=0,"",AVERAGE('Оценки'!G6:I6)) | G6: =IF('Оценки'!J6="","",'Оценки'!J6) | H6: =IF(COUNT(D6:G6)=0,"",AVERAGE(D6:G6)) | I6: =IF(OR(C6="",H6=""),"",C6-H6) | J6: =IF(I6="","",IF(I6>=0.5,"⚠ переоценивает себя",IF(H6<3,"низкий уровень","")))
A7: Смирнов А. П. (ПРИМЕР) | B7: Вовлечение руководства предприятий в федеральный проект | C7: =IF('Оценки'!K7="","",'Оценки'!K7) | D7: =IF('Оценки'!C7="","",'Оценки'!C7) | E7: =IF(COUNT('Оценки'!D7:F7)=0,"",AVERAGE('Оценки'!D7:F7)) | F7: =IF(COUNT('Оценки'!G7:I7)=0,"",AVERAGE('Оценки'!G7:I7)) | G7: =IF('Оценки'!J7="","",'Оценки'!J7) | H7: =IF(COUNT(D7:G7)=0,"",AVERAGE(D7:G7)) | I7: =IF(OR(C7="",H7=""),"",C7-H7) | J7: =IF(I7="","",IF(I7>=0.5,"⚠ переоценивает себя",IF(H7<3,"низкий уровень","")))
A8: Смирнов А. П. (ПРИМЕР) | B8: Подписание соглашения о сотрудничестве между РЦК и предприятием | C8: =IF('Оценки'!K8="","",'Оценки'!K8) | D8: =IF('Оценки'!C8="","",'Оценки'!C8) | E8: =IF(COUNT('Оценки'!D8:F8)=0,"",AVERAGE('Оценки'!D8:F8)) | F8: =IF(COUNT('Оценки'!G8:I8)=0,"",AVERAGE('Оценки'!G8:I8)) | G8: =IF('Оценки'!J8="","",'Оценки'!J8) | H8: =IF(COUNT(D8:G8)=0,"",AVERAGE(D8:G8)) | I8: =IF(OR(C8="",H8=""),"",C8-H8) | J8: =IF(I8="","",IF(I8>=0.5,"⚠ переоценивает себя",IF(H8<3,"низкий уровень","")))
A9: Смирнов А. П. (ПРИМЕР) | B9: Реализация организационных вех программы | C9: =IF('Оценки'!K9="","",'Оценки'!K9) | D9: =IF('Оценки'!C9="","",'Оценки'!C9) | E9: =IF(COUNT('Оценки'!D9:F9)=0,"",AVERAGE('Оценки'!D9:F9)) | F9: =IF(COUNT('Оценки'!G9:I9)=0,"",AVERAGE('Оценки'!G9:I9)) | G9: =IF('Оценки'!J9="","",'Оценки'!J9) | H9: =IF(COUNT(D9:G9)=0,"",AVERAGE(D9:G9)) | I9: =IF(OR(C9="",H9=""),"",C9-H9) | J9: =IF(I9="","",IF(I9>=0.5,"⚠ переоценивает себя",IF(H9<3,"низкий уровень","")))
A10: Смирнов А. П. (ПРИМЕР) | B10: Формирование проектного офиса | C10: =IF('Оценки'!K10="","",'Оценки'!K10) | D10: =IF('Оценки'!C10="","",'Оценки'!C10) | E10: =IF(COUNT('Оценки'!D10:F10)=0,"",AVERAGE('Оценки'!D10:F10)) | F10: =IF(COUNT('Оценки'!G10:I10)=0,"",AVERAGE('Оценки'!G10:I10)) | G10: =IF('Оценки'!J10="","",'Оценки'!J10) | H10: =IF(COUNT(D10:G10)=0,"",AVERAGE(D10:G10)) | I10: =IF(OR(C10="",H10=""),"",C10-H10) | J10: =IF(I10="","",IF(I10>=0.5,"⚠ переоценивает себя",IF(H10<3,"низкий уровень","")))
A11: Смирнов А. П. (ПРИМЕР) | B11: Определение перечня вовлеченных лиц и рамок проекта; создание рабочей группы для работы с пилотным потоком | C11: =IF('Оценки'!K11="","",'Оценки'!K11) | D11: =IF('Оценки'!C11="","",'Оценки'!C11) | E11: =IF(COUNT('Оценки'!D11:F11)=0,"",AVERAGE('Оценки'!D11:F11)) | F11: =IF(COUNT('Оценки'!G11:I11)=0,"",AVERAGE('Оценки'!G11:I11)) | G11: =IF('Оценки'!J11="","",'Оценки'!J11) | H11: =IF(COUNT(D11:G11)=0,"",AVERAGE(D11:G11)) | I11: =IF(OR(C11="",H11=""),"",C11-H11) | J11: =IF(I11="","",IF(I11>=0.5,"⚠ переоценивает себя",IF(H11<3,"низкий уровень","")))
A12: Смирнов А. П. (ПРИМЕР) | B12: Выявление степени готовности предприятия к изменениям | C12: =IF('Оценки'!K12="","",'Оценки'!K12) | D12: =IF('Оценки'!C12="","",'Оценки'!C12) | E12: =IF(COUNT('Оценки'!D12:F12)=0,"",AVERAGE('Оценки'!D12:F12)) | F12: =IF(COUNT('Оценки'!G12:I12)=0,"",AVERAGE('Оценки'!G12:I12)) | G12: =IF('Оценки'!J12="","",'Оценки'!J12) | H12: =IF(COUNT(D12:G12)=0,"",AVERAGE(D12:G12)) | I12: =IF(OR(C12="",H12=""),"",C12-H12) | J12: =IF(I12="","",IF(I12>=0.5,"⚠ переоценивает себя",IF(H12<3,"низкий уровень","")))
A13: Смирнов А. П. (ПРИМЕР) | B13: Составление плана ключевых событий | C13: =IF('Оценки'!K13="","",'Оценки'!K13) | D13: =IF('Оценки'!C13="","",'Оценки'!C13) | E13: =IF(COUNT('Оценки'!D13:F13)=0,"",AVERAGE('Оценки'!D13:F13)) | F13: =IF(COUNT('Оценки'!G13:I13)=0,"",AVERAGE('Оценки'!G13:I13)) | G13: =IF('Оценки'!J13="","",'Оценки'!J13) | H13: =IF(COUNT(D13:G13)=0,"",AVERAGE(D13:G13)) | I13: =IF(OR(C13="",H13=""),"",C13-H13) | J13: =IF(I13="","",IF(I13>=0.5,"⚠ переоценивает себя",IF(H13<3,"низкий уровень","")))
A14: Смирнов А. П. (ПРИМЕР) | B14: Разработка и корректировка плана мероприятий (основные этапы, сроки, ответственные) по достижению целевого состояния | C14: =IF('Оценки'!K14="","",'Оценки'!K14) | D14: =IF('Оценки'!C14="","",'Оценки'!C14) | E14: =IF(COUNT('Оценки'!D14:F14)=0,"",AVERAGE('Оценки'!D14:F14)) | F14: =IF(COUNT('Оценки'!G14:I14)=0,"",AVERAGE('Оценки'!G14:I14)) | G14: =IF('Оценки'!J14="","",'Оценки'!J14) | H14: =IF(COUNT(D14:G14)=0,"",AVERAGE(D14:G14)) | I14: =IF(OR(C14="",H14=""),"",C14-H14) | J14: =IF(I14="","",IF(I14>=0.5,"⚠ переоценивает себя",IF(H14<3,"низкий уровень","")))
A15: Смирнов А. П. (ПРИМЕР) | B15: Проведение анализа показателей проектов повышения производительности труда | C15: =IF('Оценки'!K15="","",'Оценки'!K15) | D15: =IF('Оценки'!C15="","",'Оценки'!C15) | E15: =IF(COUNT('Оценки'!D15:F15)=0,"",AVERAGE('Оценки'!D15:F15)) | F15: =IF(COUNT('Оценки'!G15:I15)=0,"",AVERAGE('Оценки'!G15:I15)) | G15: =IF('Оценки'!J15="","",'Оценки'!J15) | H15: =IF(COUNT(D15:G15)=0,"",AVERAGE(D15:G15)) | I15: =IF(OR(C15="",H15=""),"",C15-H15) | J15: =IF(I15="","",IF(I15>=0.5,"⚠ переоценивает себя",IF(H15<3,"низкий уровень","")))
... A40: Смирнов А. П. (ПРИМЕР) | B40: Ведение мониторинга проектов в подсистеме «Совместная работа» на ИТ-платформе | C40: =IF('Оценки'!K40="","",'Оценки'!K40) | D40: =IF('Оценки'!C40="","",'Оценки'!C40) | E40: =IF(COUNT('Оценки'!D40:F40)=0,"",AVERAGE('Оценки'!D40:F40)) | F40: =IF(COUNT('Оценки'!G40:I40)=0,"",AVERAGE('Оценки'!G40:I40)) | G40: =IF('Оценки'!J40="","",'Оценки'!J40) | H40: =IF(COUNT(D40:G40)=0,"",AVERAGE(D40:G40)) | I40: =IF(OR(C40="",H40=""),"",C40-H40) | J40: =IF(I40="","",IF(I40>=0.5,"⚠ переоценивает себя",IF(H40<3,"низкий уровень","")))
A41: Смирнов А. П. (ПРИМЕР) | B41: ИТОГО (среднее по всем компетенциям) | C41: =IF(COUNT(C4:C40)=0,"",AVERAGE(C4:C40)) | D41: =IF(COUNT(D4:D40)=0,"",AVERAGE(D4:D40)) | E41: =IF(COUNT(E4:E40)=0,"",AVERAGE(E4:E40)) | F41: =IF(COUNT(F4:F40)=0,"",AVERAGE(F4:F40)) | G41: =IF(COUNT(G4:G40)=0,"",AVERAGE(G4:G40)) | H41: =IF(COUNT(H4:H40)=0,"",AVERAGE(H4:H40)) | I41: =IF(OR(C41="",H41=""),"",C41-H41) | J41: =IF(I41="","",IF(I41>=0.5,"⚠ переоценивает себя",IF(H41<3,"низкий уровень","")))
A43: РП-2 | B43: Проведение оценки на соответствие предприятия обязательным критериям | C43: =IF('Оценки'!K43="","",'Оценки'!K43) | D43: =IF('Оценки'!C43="","",'Оценки'!C43) | E43: =IF(COUNT('Оценки'!D43:F43)=0,"",AVERAGE('Оценки'!D43:F43)) | F43: =IF(COUNT('Оценки'!G43:I43)=0,"",AVERAGE('Оценки'!G43:I43)) | G43: =IF('Оценки'!J43="","",'Оценки'!J43) | H43: =IF(COUNT(D43:G43)=0,"",AVERAGE(D43:G43)) | I43: =IF(OR(C43="",H43=""),"",C43-H43) | J43: =IF(I43="","",IF(I43>=0.5,"⚠ переоценивает себя",IF(H43<3,"низкий уровень","")))
A44: РП-2 | B44: Проведение оценки готовности руководства предприятия к участию в проекте (интервью) | C44: =IF('Оценки'!K44="","",'Оценки'!K44) | D44: =IF('Оценки'!C44="","",'Оценки'!C44) | E44: =IF(COUNT('Оценки'!D44:F44)=0,"",AVERAGE('Оценки'!D44:F44)) | F44: =IF(COUNT('Оценки'!G44:I44)=0,"",AVERAGE('Оценки'!G44:I44)) | G44: =IF('Оценки'!J44="","",'Оценки'!J44) | H44: =IF(COUNT(D44:G44)=0,"",AVERAGE(D44:G44)) | I44: =IF(OR(C44="",H44=""),"",C44-H44) | J44: =IF(I44="","",IF(I44>=0.5,"⚠ переоценивает себя",IF(H44<3,"низкий уровень","")))
A45: РП-2 | B45: Проведение визуальной оценки производственного процесса на предприятии (визит на площадку) | C45: =IF('Оценки'!K45="","",'Оценки'!K45) | D45: =IF('Оценки'!C45="","",'Оценки'!C45) | E45: =IF(COUNT('Оценки'!D45:F45)=0,"",AVERAGE('Оценки'!D45:F45)) | F45: =IF(COUNT('Оценки'!G45:I45)=0,"",AVERAGE('Оценки'!G45:I45)) | G45: =IF('Оценки'!J45="","",'Оценки'!J45) | H45: =IF(COUNT(D45:G45)=0,"",AVERAGE(D45:G45)) | I45: =IF(OR(C45="",H45=""),"",C45-H45) | J45: =IF(I45="","",IF(I45>=0.5,"⚠ переоценивает себя",IF(H45<3,"низкий уровень","")))
A46: РП-2 | B46: Вовлечение руководства предприятий в федеральный проект | C46: =IF('Оценки'!K46="","",'Оценки'!K46) | D46: =IF('Оценки'!C46="","",'Оценки'!C46) | E46: =IF(COUNT('Оценки'!D46:F46)=0,"",AVERAGE('Оценки'!D46:F46)) | F46: =IF(COUNT('Оценки'!G46:I46)=0,"",AVERAGE('Оценки'!G46:I46)) | G46: =IF('Оценки'!J46="","",'Оценки'!J46) | H46: =IF(COUNT(D46:G46)=0,"",AVERAGE(D46:G46)) | I46: =IF(OR(C46="",H46=""),"",C46-H46) | J46: =IF(I46="","",IF(I46>=0.5,"⚠ переоценивает себя",IF(H46<3,"низкий уровень","")))
A47: РП-2 | B47: Подписание соглашения о сотрудничестве между РЦК и предприятием | C47: =IF('Оценки'!K47="","",'Оценки'!K47) | D47: =IF('Оценки'!C47="","",'Оценки'!C47) | E47: =IF(COUNT('Оценки'!D47:F47)=0,"",AVERAGE('Оценки'!D47:F47)) | F47: =IF(COUNT('Оценки'!G47:I47)=0,"",AVERAGE('Оценки'!G47:I47)) | G47: =IF('Оценки'!J47="","",'Оценки'!J47) | H47: =IF(COUNT(D47:G47)=0,"",AVERAGE(D47:G47)) | I47: =IF(OR(C47="",H47=""),"",C47-H47) | J47: =IF(I47="","",IF(I47>=0.5,"⚠ переоценивает себя",IF(H47<3,"низкий уровень","")))
A48: РП-2 | B48: Реализация организационных вех программы | C48: =IF('Оценки'!K48="","",'Оценки'!K48) | D48: =IF('Оценки'!C48="","",'Оценки'!C48) | E48: =IF(COUNT('Оценки'!D48:F48)=0,"",AVERAGE('Оценки'!D48:F48)) | F48: =IF(COUNT('Оценки'!G48:I48)=0,"",AVERAGE('Оценки'!G48:I48)) | G48: =IF('Оценки'!J48="","",'Оценки'!J48) | H48: =IF(COUNT(D48:G48)=0,"",AVERAGE(D48:G48)) | I48: =IF(OR(C48="",H48=""),"",C48-H48) | J48: =IF(I48="","",IF(I48>=0.5,"⚠ переоценивает себя",IF(H48<3,"низкий уровень","")))
A49: РП-2 | B49: Формирование проектного офиса | C49: =IF('Оценки'!K49="","",'Оценки'!K49) | D49: =IF('Оценки'!C49="","",'Оценки'!C49) | E49: =IF(COUNT('Оценки'!D49:F49)=0,"",AVERAGE('Оценки'!D49:F49)) | F49: =IF(COUNT('Оценки'!G49:I49)=0,"",AVERAGE('Оценки'!G49:I49)) | G49: =IF('Оценки'!J49="","",'Оценки'!J49) | H49: =IF(COUNT(D49:G49)=0,"",AVERAGE(D49:G49)) | I49: =IF(OR(C49="",H49=""),"",C49-H49) | J49: =IF(I49="","",IF(I49>=0.5,"⚠ переоценивает себя",IF(H49<3,"низкий уровень","")))
A50: РП-2 | B50: Определение перечня вовлеченных лиц и рамок проекта; создание рабочей группы для работы с пилотным потоком | C50: =IF('Оценки'!K50="","",'Оценки'!K50) | D50: =IF('Оценки'!C50="","",'Оценки'!C50) | E50: =IF(COUNT('Оценки'!D50:F50)=0,"",AVERAGE('Оценки'!D50:F50)) | F50: =IF(COUNT('Оценки'!G50:I50)=0,"",AVERAGE('Оценки'!G50:I50)) | G50: =IF('Оценки'!J50="","",'Оценки'!J50) | H50: =IF(COUNT(D50:G50)=0,"",AVERAGE(D50:G50)) | I50: =IF(OR(C50="",H50=""),"",C50-H50) | J50: =IF(I50="","",IF(I50>=0.5,"⚠ переоценивает себя",IF(H50<3,"низкий уровень","")))
A51: РП-2 | B51: Выявление степени готовности предприятия к изменениям | C51: =IF('Оценки'!K51="","",'Оценки'!K51) | D51: =IF('Оценки'!C51="","",'Оценки'!C51) | E51: =IF(COUNT('Оценки'!D51:F51)=0,"",AVERAGE('Оценки'!D51:F51)) | F51: =IF(COUNT('Оценки'!G51:I51)=0,"",AVERAGE('Оценки'!G51:I51)) | G51: =IF('Оценки'!J51="","",'Оценки'!J51) | H51: =IF(COUNT(D51:G51)=0,"",AVERAGE(D51:G51)) | I51: =IF(OR(C51="",H51=""),"",C51-H51) | J51: =IF(I51="","",IF(I51>=0.5,"⚠ переоценивает себя",IF(H51<3,"низкий уровень","")))
A52: РП-2 | B52: Составление плана ключевых событий | C52: =IF('Оценки'!K52="","",'Оценки'!K52) | D52: =IF('Оценки'!C52="","",'Оценки'!C52) | E52: =IF(COUNT('Оценки'!D52:F52)=0,"",AVERAGE('Оценки'!D52:F52)) | F52: =IF(COUNT('Оценки'!G52:I52)=0,"",AVERAGE('Оценки'!G52:I52)) | G52: =IF('Оценки'!J52="","",'Оценки'!J52) | H52: =IF(COUNT(D52:G52)=0,"",AVERAGE(D52:G52)) | I52: =IF(OR(C52="",H52=""),"",C52-H52) | J52: =IF(I52="","",IF(I52>=0.5,"⚠ переоценивает себя",IF(H52<3,"низкий уровень","")))
A53: РП-2 | B53: Разработка и корректировка плана мероприятий (основные этапы, сроки, ответственные) по достижению целевого состояния | C53: =IF('Оценки'!K53="","",'Оценки'!K53) | D53: =IF('Оценки'!C53="","",'Оценки'!C53) | E53: =IF(COUNT('Оценки'!D53:F53)=0,"",AVERAGE('Оценки'!D53:F53)) | F53: =IF(COUNT('Оценки'!G53:I53)=0,"",AVERAGE('Оценки'!G53:I53)) | G53: =IF('Оценки'!J53="","",'Оценки'!J53) | H53: =IF(COUNT(D53:G53)=0,"",AVERAGE(D53:G53)) | I53: =IF(OR(C53="",H53=""),"",C53-H53) | J53: =IF(I53="","",IF(I53>=0.5,"⚠ переоценивает себя",IF(H53<3,"низкий уровень","")))
A54: РП-2 | B54: Проведение анализа показателей проектов повышения производительности труда | C54: =IF('Оценки'!K54="","",'Оценки'!K54) | D54: =IF('Оценки'!C54="","",'Оценки'!C54) | E54: =IF(COUNT('Оценки'!D54:F54)=0,"",AVERAGE('Оценки'!D54:F54)) | F54: =IF(COUNT('Оценки'!G54:I54)=0,"",AVERAGE('Оценки'!G54:I54)) | G54: =IF('Оценки'!J54="","",'Оценки'!J54) | H54: =IF(COUNT(D54:G54)=0,"",AVERAGE(D54:G54)) | I54: =IF(OR(C54="",H54=""),"",C54-H54) | J54: =IF(I54="","",IF(I54>=0.5,"⚠ переоценивает себя",IF(H54<3,"низкий уровень","")))
... A79: РП-2 | B79: Ведение мониторинга проектов в подсистеме «Совместная работа» на ИТ-платформе | C79: =IF('Оценки'!K79="","",'Оценки'!K79) | D79: =IF('Оценки'!C79="","",'Оценки'!C79) | E79: =IF(COUNT('Оценки'!D79:F79)=0,"",AVERAGE('Оценки'!D79:F79)) | F79: =IF(COUNT('Оценки'!G79:I79)=0,"",AVERAGE('Оценки'!G79:I79)) | G79: =IF('Оценки'!J79="","",'Оценки'!J79) | H79: =IF(COUNT(D79:G79)=0,"",AVERAGE(D79:G79)) | I79: =IF(OR(C79="",H79=""),"",C79-H79) | J79: =IF(I79="","",IF(I79>=0.5,"⚠ переоценивает себя",IF(H79<3,"низкий уровень","")))
A80: РП-2 | B80: ИТОГО (среднее по всем компетенциям) | C80: =IF(COUNT(C43:C79)=0,"",AVERAGE(C43:C79)) | D80: =IF(COUNT(D43:D79)=0,"",AVERAGE(D43:D79)) | E80: =IF(COUNT(E43:E79)=0,"",AVERAGE(E43:E79)) | F80: =IF(COUNT(F43:F79)=0,"",AVERAGE(F43:F79)) | G80: =IF(COUNT(G43:G79)=0,"",AVERAGE(G43:G79)) | H80: =IF(COUNT(H43:H79)=0,"",AVERAGE(H43:H79)) | I80: =IF(OR(C80="",H80=""),"",C80-H80) | J80: =IF(I80="","",IF(I80>=0.5,"⚠ переоценивает себя",IF(H80<3,"низкий уровень","")))
A82: РП-3 | B82: Проведение оценки на соответствие предприятия обязательным критериям | C82: =IF('Оценки'!K82="","",'Оценки'!K82) | D82: =IF('Оценки'!C82="","",'Оценки'!C82) | E82: =IF(COUNT('Оценки'!D82:F82)=0,"",AVERAGE('Оценки'!D82:F82)) | F82: =IF(COUNT('Оценки'!G82:I82)=0,"",AVERAGE('Оценки'!G82:I82)) | G82: =IF('Оценки'!J82="","",'Оценки'!J82) | H82: =IF(COUNT(D82:G82)=0,"",AVERAGE(D82:G82)) | I82: =IF(OR(C82="",H82=""),"",C82-H82) | J82: =IF(I82="","",IF(I82>=0.5,"⚠ переоценивает себя",IF(H82<3,"низкий уровень","")))
A83: РП-3 | B83: Проведение оценки готовности руководства предприятия к участию в проекте (интервью) | C83: =IF('Оценки'!K83="","",'Оценки'!K83) | D83: =IF('Оценки'!C83="","",'Оценки'!C83) | E83: =IF(COUNT('Оценки'!D83:F83)=0,"",AVERAGE('Оценки'!D83:F83)) | F83: =IF(COUNT('Оценки'!G83:I83)=0,"",AVERAGE('Оценки'!G83:I83)) | G83: =IF('Оценки'!J83="","",'Оценки'!J83) | H83: =IF(COUNT(D83:G83)=0,"",AVERAGE(D83:G83)) | I83: =IF(OR(C83="",H83=""),"",C83-H83) | J83: =IF(I83="","",IF(I83>=0.5,"⚠ переоценивает себя",IF(H83<3,"низкий уровень","")))
A84: РП-3 | B84: Проведение визуальной оценки производственного процесса на предприятии (визит на площадку) | C84: =IF('Оценки'!K84="","",'Оценки'!K84) | D84: =IF('Оценки'!C84="","",'Оценки'!C84) | E84: =IF(COUNT('Оценки'!D84:F84)=0,"",AVERAGE('Оценки'!D84:F84)) | F84: =IF(COUNT('Оценки'!G84:I84)=0,"",AVERAGE('Оценки'!G84:I84)) | G84: =IF('Оценки'!J84="","",'Оценки'!J84) | H84: =IF(COUNT(D84:G84)=0,"",AVERAGE(D84:G84)) | I84: =IF(OR(C84="",H84=""),"",C84-H84) | J84: =IF(I84="","",IF(I84>=0.5,"⚠ переоценивает себя",IF(H84<3,"низкий уровень","")))
A85: РП-3 | B85: Вовлечение руководства предприятий в федеральный проект | C85: =IF('Оценки'!K85="","",'Оценки'!K85) | D85: =IF('Оценки'!C85="","",'Оценки'!C85) | E85: =IF(COUNT('Оценки'!D85:F85)=0,"",AVERAGE('Оценки'!D85:F85)) | F85: =IF(COUNT('Оценки'!G85:I85)=0,"",AVERAGE('Оценки'!G85:I85)) | G85: =IF('Оценки'!J85="","",'Оценки'!J85) | H85: =IF(COUNT(D85:G85)=0,"",AVERAGE(D85:G85)) | I85: =IF(OR(C85="",H85=""),"",C85-H85) | J85: =IF(I85="","",IF(I85>=0.5,"⚠ переоценивает себя",IF(H85<3,"низкий уровень","")))
A86: РП-3 | B86: Подписание соглашения о сотрудничестве между РЦК и предприятием | C86: =IF('Оценки'!K86="","",'Оценки'!K86) | D86: =IF('Оценки'!C86="","",'Оценки'!C86) | E86: =IF(COUNT('Оценки'!D86:F86)=0,"",AVERAGE('Оценки'!D86:F86)) | F86: =IF(COUNT('Оценки'!G86:I86)=0,"",AVERAGE('Оценки'!G86:I86)) | G86: =IF('Оценки'!J86="","",'Оценки'!J86) | H86: =IF(COUNT(D86:G86)=0,"",AVERAGE(D86:G86)) | I86: =IF(OR(C86="",H86=""),"",C86-H86) | J86: =IF(I86="","",IF(I86>=0.5,"⚠ переоценивает себя",IF(H86<3,"низкий уровень","")))
A87: РП-3 | B87: Реализация организационных вех программы | C87: =IF('Оценки'!K87="","",'Оценки'!K87) | D87: =IF('Оценки'!C87="","",'Оценки'!C87) | E87: =IF(COUNT('Оценки'!D87:F87)=0,"",AVERAGE('Оценки'!D87:F87)) | F87: =IF(COUNT('Оценки'!G87:I87)=0,"",AVERAGE('Оценки'!G87:I87)) | G87: =IF('Оценки'!J87="","",'Оценки'!J87) | H87: =IF(COUNT(D87:G87)=0,"",AVERAGE(D87:G87)) | I87: =IF(OR(C87="",H87=""),"",C87-H87) | J87: =IF(I87="","",IF(I87>=0.5,"⚠ переоценивает себя",IF(H87<3,"низкий уровень","")))
A88: РП-3 | B88: Формирование проектного офиса | C88: =IF('Оценки'!K88="","",'Оценки'!K88) | D88: =IF('Оценки'!C88="","",'Оценки'!C88) | E88: =IF(COUNT('Оценки'!D88:F88)=0,"",AVERAGE('Оценки'!D88:F88)) | F88: =IF(COUNT('Оценки'!G88:I88)=0,"",AVERAGE('Оценки'!G88:I88)) | G88: =IF('Оценки'!J88="","",'Оценки'!J88) | H88: =IF(COUNT(D88:G88)=0,"",AVERAGE(D88:G88)) | I88: =IF(OR(C88="",H88=""),"",C88-H88) | J88: =IF(I88="","",IF(I88>=0.5,"⚠ переоценивает себя",IF(H88<3,"низкий уровень","")))
A89: РП-3 | B89: Определение перечня вовлеченных лиц и рамок проекта; создание рабочей группы для работы с пилотным потоком | C89: =IF('Оценки'!K89="","",'Оценки'!K89) | D89: =IF('Оценки'!C89="","",'Оценки'!C89) | E89: =IF(COUNT('Оценки'!D89:F89)=0,"",AVERAGE('Оценки'!D89:F89)) | F89: =IF(COUNT('Оценки'!G89:I89)=0,"",AVERAGE('Оценки'!G89:I89)) | G89: =IF('Оценки'!J89="","",'Оценки'!J89) | H89: =IF(COUNT(D89:G89)=0,"",AVERAGE(D89:G89)) | I89: =IF(OR(C89="",H89=""),"",C89-H89) | J89: =IF(I89="","",IF(I89>=0.5,"⚠ переоценивает себя",IF(H89<3,"низкий уровень","")))
A90: РП-3 | B90: Выявление степени готовности предприятия к изменениям | C90: =IF('Оценки'!K90="","",'Оценки'!K90) | D90: =IF('Оценки'!C90="","",'Оценки'!C90) | E90: =IF(COUNT('Оценки'!D90:F90)=0,"",AVERAGE('Оценки'!D90:F90)) | F90: =IF(COUNT('Оценки'!G90:I90)=0,"",AVERAGE('Оценки'!G90:I90)) | G90: =IF('Оценки'!J90="","",'Оценки'!J90) | H90: =IF(COUNT(D90:G90)=0,"",AVERAGE(D90:G90)) | I90: =IF(OR(C90="",H90=""),"",C90-H90) | J90: =IF(I90="","",IF(I90>=0.5,"⚠ переоценивает себя",IF(H90<3,"низкий уровень","")))
...

Sheet План развития
A1: ПЛАН РАЗВИТИЯ СОТРУДНИКА РЦК (формат — приложение № 6 МР; заполняется после встречи, на основе «Сводки»)
A2: Уровни по шкале 360: 1–5 (см. «Инструкцию»). Для профессиональных инструментов (картирование, 5С, производственный анализ и др.) МР (приложение № 6) использует шкалу 0,0–3,0 с шагом 0,5: 0,0 — не соответствует требованиям; 0,5 — начальный уровень; 1,0 — большей частью не соответствует; 1,5 — большей частью соответствует; 2,0 — полностью соответствует; 2,5 — по некоторым направлениям превосходит; 3,0 — превосходит требования. Целевой уровень по итогам развития — не ниже 1,5 (МР). С планом ознакомлены: сотрудник РЦК, наставник, руководитель РЦК (подписи и даты).
A3: Сотрудник РЦК (ФИО) | B3: Направление работы в РЦК | C3: Компетенция (результат 360: низкий балл / разрыв) | D3: Уровень на старте (по 360) | E3: Целевой уровень | F3: Мероприятия развития (обучение, стажировка, практика, наставничество) | G3: Наставник (РП ФЦК / РЦК) | H3: Срок | I3: Оценка (факт) | J3: Статус
A4: Смирнов А. П. (ПРИМЕР) | B4: (например: Оптимизация потоков и процессов) | C4: Проведение оценки на соответствие предприятия обязательным критериям: разрыв «себя − другие» = 1.3 (себя 5.0; другие 3.7) | D4: 3.7 | E4: 5.0 | F4: Практика на площадке под наблюдением наставника (2–3 применения навыка), методический разбор с наставником, защита презентации результата; при необходимости — обучение (программы «Академии производительности») | G4: (ФИО РП ФЦК / РЦК) | H4: к концу квартала | J4: план
